Workbook

Sheet Summary
A1: GATE CS 2027 Study Tracker: 25 Oct 2026 to 5 Feb 2027 (104 days)
A2: Fill the yellow cells in the Tracker every night (Status, Aptitude, Actual Hrs, PYQs, Notes). Do 30-60 min of General Aptitude daily. Everything on this sheet updates by itself.
A4: Exam start date (edit to your CS paper date) | B4: =DATE(2027,2,6) -> 46424
A5: Days left to exam | B5: =MAX(0,B4-TODAY()) -> 105
A6: Total days in plan | B6: =COUNT(Tracker!$A$2:$A$105) -> 104
A7: Days fully done | B7: =COUNTIF(Tracker!$H$2:$H$105,"Yes") -> 0
A8: Days partly done | B8: =COUNTIF(Tracker!$H$2:$H$105,"Partial") -> 0
A9: Plan completed (%) | B9: =IF(B6=0,0,B7/B6) -> 0
A10: Missed days (past, not marked) | B10: =COUNTIFS(Tracker!$B$2:$B$105,"<"&TODAY(),Tracker!$H$2:$H$105,"") -> 0
A11: Planned hours (total) | B11: =SUM(Tracker!$G$2:$G$105) -> 660
A12: Actual hours studied | B12: =SUM(Tracker!$J$2:$J$105) -> 0
A13: Actual vs planned (%) | B13: =IF(B11=0,0,B12/B11) -> 0
A14: Total PYQs solved | B14: =SUM(Tracker!$K$2:$K$105) -> 0
A15: Days aptitude done | B15: =COUNTIF(Tracker!$I$2:$I$105,"Yes") -> 0
A16: Full mocks taken | B16: =COUNTA(Mocks!B4:B40) -> 0
A17: Average mock score (out of 100) | B17: =IF(COUNT(Mocks!C4:C40)=0,"-",AVERAGE(Mocks!C4:C40)) -> -
A20: Subject progress (learning phase)
A21: Subject | B21: Days planned | C21: Days done | D21: % done | E21: Confidence (1-5, you fill)
A22: C + Data Structures | B22: =COUNTIF(Tracker!$E$2:$E$105,A22) -> 8 | C22: =COUNTIFS(Tracker!$E$2:$E$105,A22,Tracker!$H$2:$H$105,"Yes") -> 0 | D22: =IF(B22=0,0,C22/B22) -> 0
A23: Algorithms | B23: =COUNTIF(Tracker!$E$2:$E$105,A23) -> 5 | C23: =COUNTIFS(Tracker!$E$2:$E$105,A23,Tracker!$H$2:$H$105,"Yes") -> 0 | D23: =IF(B23=0,0,C23/B23) -> 0
A24: Discrete Maths | B24: =COUNTIF(Tracker!$E$2:$E$105,A24) -> 5 | C24: =COUNTIFS(Tracker!$E$2:$E$105,A24,Tracker!$H$2:$H$105,"Yes") -> 0 | D24: =IF(B24=0,0,C24/B24) -> 0
A25: Maths (Prob, LA, Calc) | B25: =COUNTIF(Tracker!$E$2:$E$105,A25) -> 4 | C25: =COUNTIFS(Tracker!$E$2:$E$105,A25,Tracker!$H$2:$H$105,"Yes") -> 0 | D25: =IF(B25=0,0,C25/B25) -> 0
A26: Theory of Computation | B26: =COUNTIF(Tracker!$E$2:$E$105,A26) -> 3 | C26: =COUNTIFS(Tracker!$E$2:$E$105,A26,Tracker!$H$2:$H$105,"Yes") -> 0 | D26: =IF(B26=0,0,C26/B26) -> 0
A27: Operating Systems | B27: =COUNTIF(Tracker!$E$2:$E$105,A27) -> 5 | C27: =COUNTIFS(Tracker!$E$2:$E$105,A27,Tracker!$H$2:$H$105,"Yes") -> 0 | D27: =IF(B27=0,0,C27/B27) -> 0
A28: DBMS | B28: =COUNTIF(Tracker!$E$2:$E$105,A28) -> 4 | C28: =COUNTIFS(Tracker!$E$2:$E$105,A28,Tracker!$H$2:$H$105,"Yes") -> 0 | D28: =IF(B28=0,0,C28/B28) -> 0
A29: Computer Networks | B29: =COUNTIF(Tracker!$E$2:$E$105,A29) -> 4 | C29: =COUNTIFS(Tracker!$E$2:$E$105,A29,Tracker!$H$2:$H$105,"Yes") -> 0 | D29: =IF(B29=0,0,C29/B29) -> 0
A30: Computer Organization | B30: =COUNTIF(Tracker!$E$2:$E$105,A30) -> 4 | C30: =COUNTIFS(Tracker!$E$2:$E$105,A30,Tracker!$H$2:$H$105,"Yes") -> 0 | D30: =IF(B30=0,0,C30/B30) -> 0
A31: Digital Logic | B31: =COUNTIF(Tracker!$E$2:$E$105,A31) -> 2 | C31: =COUNTIFS(Tracker!$E$2:$E$105,A31,Tracker!$H$2:$H$105,"Yes") -> 0 | D31: =IF(B31=0,0,C31/B31) -> 0
A32: Compiler Design | B32: =COUNTIF(Tracker!$E$2:$E$105,A32) -> 2 | C32: =COUNTIFS(Tracker!$E$2:$E$105,A32,Tracker!$H$2:$H$105,"Yes") -> 0 | D32: =IF(B32=0,0,C32/B32) -> 0
A34: Weekly summary
A35: Week starting | B35: Planned hrs | C35: Actual hrs | D35: Days done | E35: PYQs solved
A36: =DATE(2026,10,25) -> 46320 | B36: =SUMIFS(Tracker!$G$2:$G$105,Tracker!$B$2:$B$105,">="&$A36,Tracker!$B$2:$B$105,"<="&$A36+6) -> 36.5 | C36: =SUMIFS(Tracker!$J$2:$J$105,Tracker!$B$2:$B$105,">="&$A36,Tracker!$B$2:$B$105,"<="&$A36+6) -> 0 | D36: =COUNTIFS(Tracker!$B$2:$B$105,">="&$A36,Tracker!$B$2:$B$105,"<="&$A36+6,Tracker!$H$2:$H$105,"Yes") -> 0 | E36: =SUMIFS(Tracker!$K$2:$K$105,Tracker!$B$2:$B$105,">="&$A36,Tracker!$B$2:$B$105,"<="&$A36+6) -> 0
A37: =A36+7 -> 46327 | B37: =SUMIFS(Tracker!$G$2:$G$105,Tracker!$B$2:$B$105,">="&$A37,Tracker!$B$2:$B$105,"<="&$A37+6) -> 17 | C37: =SUMIFS(Tracker!$J$2:$J$105,Tracker!$B$2:$B$105,">="&$A37,Tracker!$B$2:$B$105,"<="&$A37+6) -> 0 | D37: =COUNTIFS(Tracker!$B$2:$B$105,">="&$A37,Tracker!$B$2:$B$105,"<="&$A37+6,Tracker!$H$2:$H$105,"Yes") -> 0 | E37: =SUMIFS(Tracker!$K$2:$K$105,Tracker!$B$2:$B$105,">="&$A37,Tracker!$B$2:$B$105,"<="&$A37+6) -> 0
A38: =A37+7 -> 46334 | B38: =SUMIFS(Tracker!$G$2:$G$105,Tracker!$B$2:$B$105,">="&$A38,Tracker!$B$2:$B$105,"<="&$A38+6) -> 11 | C38: =SUMIFS(Tracker!$J$2:$J$105,Tracker!$B$2:$B$105,">="&$A38,Tracker!$B$2:$B$105,"<="&$A38+6) -> 0 | D38: =COUNTIFS(Tracker!$B$2:$B$105,">="&$A38,Tracker!$B$2:$B$105,"<="&$A38+6,Tracker!$H$2:$H$105,"Yes") -> 0 | E38: =SUMIFS(Tracker!$K$2:$K$105,Tracker!$B$2:$B$105,">="&$A38,Tracker!$B$2:$B$105,"<="&$A38+6) -> 0
A39: =A38+7 -> 46341 | B39: =SUMIFS(Tracker!$G$2:$G$105,Tracker!$B$2:$B$105,">="&$A39,Tracker!$B$2:$B$105,"<="&$A39+6) -> 41.5 | C39: =SUMIFS(Tracker!$J$2:$J$105,Tracker!$B$2:$B$105,">="&$A39,Tracker!$B$2:$B$105,"<="&$A39+6) -> 0 | D39: =COUNTIFS(Tracker!$B$2:$B$105,">="&$A39,Tracker!$B$2:$B$105,"<="&$A39+6,Tracker!$H$2:$H$105,"Yes") -> 0 | E39: =SUMIFS(Tracker!$K$2:$K$105,Tracker!$B$2:$B$105,">="&$A39,Tracker!$B$2:$B$105,"<="&$A39+6) -> 0
A40: =A39+7 -> 46348 | B40: =SUMIFS(Tracker!$G$2:$G$105,Tracker!$B$2:$B$105,">="&$A40,Tracker!$B$2:$B$105,"<="&$A40+6) -> 53 | C40: =SUMIFS(Tracker!$J$2:$J$105,Tracker!$B$2:$B$105,">="&$A40,Tracker!$B$2:$B$105,"<="&$A40+6) -> 0 | D40: =COUNTIFS(Tracker!$B$2:$B$105,">="&$A40,Tracker!$B$2:$B$105,"<="&$A40+6,Tracker!$H$2:$H$105,"Yes") -> 0 | E40: =SUMIFS(Tracker!$K$2:$K$105,Tracker!$B$2:$B$105,">="&$A40,Tracker!$B$2:$B$105,"<="&$A40+6) -> 0
A41: =A40+7 -> 46355 | B41: =SUMIFS(Tracker!$G$2:$G$105,Tracker!$B$2:$B$105,">="&$A41,Tracker!$B$2:$B$105,"<="&$A41+6) -> 53 | C41: =SUMIFS(Tracker!$J$2:$J$105,Tracker!$B$2:$B$105,">="&$A41,Tracker!$B$2:$B$105,"<="&$A41+6) -> 0 | D41: =COUNTIFS(Tracker!$B$2:$B$105,">="&$A41,Tracker!$B$2:$B$105,"<="&$A41+6,Tracker!$H$2:$H$105,"Yes") -> 0 | E41: =SUMIFS(Tracker!$K$2:$K$105,Tracker!$B$2:$B$105,">="&$A41,Tracker!$B$2:$B$105,"<="&$A41+6) -> 0
A42: =A41+7 -> 46362 | B42: =SUMIFS(Tracker!$G$2:$G$105,Tracker!$B$2:$B$105,">="&$A42,Tracker!$B$2:$B$105,"<="&$A42+6) -> 53 | C42: =SUMIFS(Tracker!$J$2:$J$105,Tracker!$B$2:$B$105,">="&$A42,Tracker!$B$2:$B$105,"<="&$A42+6) -> 0 | D42: =COUNTIFS(Tracker!$B$2:$B$105,">="&$A42,Tracker!$B$2:$B$105,"<="&$A42+6,Tracker!$H$2:$H$105,"Yes") -> 0 | E42: =SUMIFS(Tracker!$K$2:$K$105,Tracker!$B$2:$B$105,">="&$A42,Tracker!$B$2:$B$105,"<="&$A42+6) -> 0
A43: =A42+7 -> 46369 | B43: =SUMIFS(Tracker!$G$2:$G$105,Tracker!$B$2:$B$105,">="&$A43,Tracker!$B$2:$B$105,"<="&$A43+6) -> 53 | C43: =SUMIFS(Tracker!$J$2:$J$105,Tracker!$B$2:$B$105,">="&$A43,Tracker!$B$2:$B$105,"<="&$A43+6) -> 0 | D43: =COUNTIFS(Tracker!$B$2:$B$105,">="&$A43,Tracker!$B$2:$B$105,"<="&$A43+6,Tracker!$H$2:$H$105,"Yes") -> 0 | E43: =SUMIFS(Tracker!$K$2:$K$105,Tracker!$B$2:$B$105,">="&$A43,Tracker!$B$2:$B$105,"<="&$A43+6) -> 0
A44: =A43+7 -> 46376 | B44: =SUMIFS(Tracker!$G$2:$G$105,Tracker!$B$2:$B$105,">="&$A44,Tracker!$B$2:$B$105,"<="&$A44+6) -> 53 | C44: =SUMIFS(Tracker!$J$2:$J$105,Tracker!$B$2:$B$105,">="&$A44,Tracker!$B$2:$B$105,"<="&$A44+6) -> 0 | D44: =COUNTIFS(Tracker!$B$2:$B$105,">="&$A44,Tracker!$B$2:$B$105,"<="&$A44+6,Tracker!$H$2:$H$105,"Yes") -> 0 | E44: =SUMIFS(Tracker!$K$2:$K$105,Tracker!$B$2:$B$105,">="&$A44,Tracker!$B$2:$B$105,"<="&$A44+6) -> 0
...

Sheet Tracker
A1: Day | B1: Date | C1: Weekday | D1: Phase | E1: Subject / Focus | F1: Today's Tasks | G1: Planned Hrs | H1: Status | I1: Aptitude done? | J1: Actual Hrs | K1: PYQs Solved | L1: Notes
A2: 1 | B2: =DATE(2026,10,25) -> 46320 | C2: =TEXT(B2,"ddd") -> Sun | D2: Phase 1: Start | E2: C + Data Structures | F2: Learn/solve: C basics: pointers, arrays, strings, storage classes | G2: 5
A3: 2 | B3: =B2+1 -> 46321 | C3: =TEXT(B3,"ddd") -> Mon | D3: Phase 1: Start | E3: C + Data Structures | F3: Learn/solve: C: functions, recursion, output tracing | G3: 4.5
A4: 3 | B4: =B3+1 -> 46322 | C4: =TEXT(B4,"ddd") -> Tue | D4: Phase 1: Start | E4: C + Data Structures | F4: Learn/solve: Linked list, stack, queue | G4: 4.5
A5: 4 | B5: =B4+1 -> 46323 | C5: =TEXT(B5,"ddd") -> Wed | D5: Phase 1: Start | E5: C + Data Structures | F5: Learn/solve: Trees, BST, heaps | G5: 4.5
A6: 5 | B6: =B5+1 -> 46324 | C6: =TEXT(B6,"ddd") -> Thu | D6: Phase 1: Start | E6: C + Data Structures | F6: Learn/solve: AVL, hashing, graph basics | G6: 4.5
A7: 6 | B7: =B6+1 -> 46325 | C7: =TEXT(B7,"ddd") -> Fri | D7: Phase 1: Start | E7: C + Data Structures | F7: Learn/solve: Mixed C + DS PYQs (timed) | G7: 4.5
A8: 7 | B8: =B7+1 -> 46326 | C8: =TEXT(B8,"ddd") -> Sat | D8: Phase 1: Start | E8: C + Data Structures | F8: Learn/solve: Mixed C + DS PYQs, fix weak spots | G8: 9
A9: 8 | B9: =B8+1 -> 46327 | C9: =TEXT(B9,"ddd") -> Sun | D9: Phase 1: Start | E9: C + Data Structures | F9: Weekly test: 30-40 timed PYQs on C + DS. Then check mistakes. | G9: 5
A10: 9 | B10: =B9+1 -> 46328 | C10: =TEXT(B10,"ddd") -> Mon | D10: Phase 2: Exams | E10: College exams (light GATE) | F10: Mid exams: 30 min aptitude + 1.5 hr PYQs (C/DS or your exam subject). No new topics. Skip GATE the day before an exam. | G10: 2
A11: 10 | B11: =B10+1 -> 46329 | C11: =TEXT(B11,"ddd") -> Tue | D11: Phase 2: Exams | E11: College exams (light GATE) | F11: Mid exams: 30 min aptitude + 1.5 hr PYQs (C/DS or your exam subject). No new topics. Skip GATE the day before an exam. | G11: 2
A12: 11 | B12: =B11+1 -> 46330 | C12: =TEXT(B12,"ddd") -> Wed | D12: Phase 2: Exams | E12: College exams (light GATE) | F12: Mid exams: 30 min aptitude + 1.5 hr PYQs (C/DS or your exam subject). No new topics. Skip GATE the day before an exam. | G12: 2
A13: 12 | B13: =B12+1 -> 46331 | C13: =TEXT(B13,"ddd") -> Thu | D13: Phase 2: Exams | E13: College exams (light GATE) | F13: Mid exams: 30 min aptitude + 1.5 hr PYQs (C/DS or your exam subject). No new topics. Skip GATE the day before an exam. | G13: 2
A14: 13 | B14: =B13+1 -> 46332 | C14: =TEXT(B14,"ddd") -> Fri | D14: Phase 2: Exams | E14: College exams (light GATE) | F14: Mid exams: 30 min aptitude + 1.5 hr PYQs (C/DS or your exam subject). No new topics. Skip GATE the day before an exam. | G14: 2
... A105: 104 | B105: =B104+1 -> 46423 | C105: =TEXT(B105,"ddd") -> Fri | D105: Phase 6: Final | E105: Rest | F105: Rest. Check admit card, exam centre, ID. Early sleep. | G105: 0

Sheet Mocks
A1: Mock test log (aim: 55-60+ out of 100 before the exam; top-1000 usually needs the 60s)
A2: Mock # | B2: Date | C2: Score (/100) | D2: Marks lost: concept gap | E2: Marks lost: silly mistake | F2: Marks lost: time pressure | G2: Weak topics to fix
A3: 1 | B3: =DATE(2026,12,27) -> 46383 | C3: 34 | D3: 12 | E3: 8 | F3: 6 | G3: Example row: replace with your own (OS scheduling, CN subnetting)

Sheet Mistake Log
A1: Mistake notebook: write every wrong question here, review it for 30 min daily
A2: Date | B2: Subject | C2: Topic | D2: Source (year/mock) | E2: Mistake type | F2: What went wrong | G2: Correct idea / formula | H2: Revised? (Yes/No)
A3: =DATE(2026,12,5) -> 46361 | B3: Operating Systems | C3: Round robin | D3: GATE 2019 | E3: Concept | F3: Forgot to count context switch time | G3: Add switch time to every slice change | H3: No

Sheet Syllabus 2027
A1: GATE CS 2027 syllabus changes vs 2026 (7 of 10 sections unchanged)
A2: Subject | B2: What changed | C2: What to do
A3: Computer Networks | B3: REMOVED (no longer listed): OSI + TCP/IP stacks, framing, Ethernet bridging, shortest-path + flooding as separate entries, ARP, DHCP, ICMP, UDP, SMTP, FTP, Email. NEW: performance metrics for switching. Application layer = DNS + HTTP only. | C3: Skip the removed topics. Keep: layering principles, switching, error detection, MAC, Ethernet, distance vector, link state, IPv4 fragmentation, CIDR, NAT, TCP flow/congestion control, socket API, DNS, HTTP.
A4: Computer Organization | B4: NEWLY NAMED: design of ALU, hardwired + microprogrammed control unit, memory interfacing, memory performance, cache mapping. No longer named: data-path, main memory, secondary storage. | C4: Add control unit design + memory interfacing. Keep cache mapping as the core. Disk calculations: not clearly removed, so keep a few.
A5: Digital Logic | B5: Minimization methods now named: algebraic, K-map, tabular method. Now says DESIGN of combinational + sequential circuits. Number representation + arithmetic (fixed + floating point) stays. | C5: Learn the tabular (Quine-McCluskey) method. Practise designing circuits from a word description.
A6: All other sections | B6: Engineering Maths, C + DS, Algorithms, TOC, Compiler Design, OS, DBMS: word for word the same as 2026. | C6: No change. Old PYQs and notes are still valid.
A7: Old PYQs | B7: Past questions on OSI layers, ARP, ICMP, SMTP, FTP, DHCP, UDP are now outside the syllabus. | C7: Skip those PYQs when solving CN.
A9: Source: official GATE 2027 CS syllabus PDF (IIT Madras) as compared with the 2026 syllabus by prosyllabus.com (checked 30 Sep 2026). The organiser has not published an itemised change list, so confirm against gate2027.iitm.ac.in.
